Workbook

Sheet Readme
A1: This verification plan is NOT intended to be considered complete nor standalone.
A2: It is covering all the missing feature that formal verification was not able to verify for various reasons (complexity, run time, …)
A3: Please also refer to the corresponding Formal Verification Plans to have a complete view on what is verified.

Sheet XPULP_POSTINC_LOAD-STORE
A1: Requirement Location | B1: Feature | C1: Sub Feature | D1: Feature Description | E1: Verification Goal | F1: Pass/Fail Criteria | G1: Test-Program Type | H1: UVM Test Config | I1: Coverage Method | J1: Test-Program(s) Name(s) | K1: Link to Coverage | L1: Comments | M1: GVSOC ISS Status | N1: GVSOC Witness (lane [config] verdetto gate) | O1: GVSOC Note
A2: CV32E40P User Manual - Chapter 18.1.1 | B2: Load Operations - Register-Immediate Loads with Post-Increment | C2: CV.LB.II | D2: cv.lb rD, Imm(rs1!) rD = Sext(Mem8(rs1)) rs1 += Sext(Imm[11:0]) | E2: Register operands All possible rs1 registers are used. All possible rD registers are used. All possible register combinations where first operand is the destination register of the previous instruction | F2: Check against RM | G2: Constrained-Random | H2: see CV32E40Pv2_test_list.xlsx | I2: Functional Coverage | J2: corev_rand_pulp_instr_test pulp_post_increment_load_store | K2: =SUBSTITUTE(DONOTDELETE!$A$14,"INSTR",SUBSTITUTE(LOWER($C2),".","_")) & IF(ISNUMBER(SEARCH("rs2",D2)),CHAR(10) & SUBSTITUTE(DONOTDELETE!$A$17,"INSTR",SUBSTITUTE(LOWER($C2),".","_")),"") | M2: COVERED-GVSOC | N2: corev_rand_pulp_instr_test:A/C2 pulp_post_increment_load_store:A/C1
E3: coverage: All bits of rs1 are toggled All bits of Imm12 are toggled All bits of rD are toggled | F3: Check against RM | G3: Constrained-Random | H3: see CV32E40Pv2_test_list.xlsx | I3: Functional Coverage | J3: corev_rand_pulp_instr_test pulp_post_increment_load_store | K3: =SUBSTITUTE(DONOTDELETE!$A$15,"INSTR",SUBSTITUTE(LOWER($C2),".","_")) & IF(ISNUMBER(SEARCH("rs2",D2)),CHAR(10) & SUBSTITUTE(DONOTDELETE!$A$18,"INSTR",SUBSTITUTE(LOWER($C2),".","_")),"") | L3: Toggle is not a requirement of CV32E40Pv2 verification, but the corresponding coverage from the Reference Model Coverage Package exists and is given for reference purposes only. Immediate toggle coverage is missing from Reference Model Coverage Package. | M3: COVERED-GVSOC | N3: corev_rand_pulp_instr_test:A/C2 pulp_post_increment_load_store:A/C1
E4: Constraints: The instructions generated are precedeed by a multicycle F instruction | F4: Check against RM | G4: Constrained-Random | H4: see CV32E40Pv2_test_list.xlsx | I4: Functional Coverage | J4: corev_rand_fp_instr_mlt_cyc_test | M4: COVERED-GVSOC | N4: corev_rand_fp_instr_mlt_cyc_test:A
C5: CV.LBU.II | D5: cv.lbu rD, Imm(rs1!) rD = Zext(Mem8(rs1)) rs1 += Sext(Imm[11:0]) | E5: Register operands All possible rs1 registers are used. All possible rD registers are used. All possible register combinations where first operand is the destination register of the previous instruction | F5: Check against RM | G5: Constrained-Random | H5: see CV32E40Pv2_test_list.xlsx | I5: Functional Coverage | J5: corev_rand_pulp_instr_test pulp_post_increment_load_store | K5: =SUBSTITUTE(DONOTDELETE!$A$14,"INSTR",SUBSTITUTE(LOWER($C5),".","_")) & IF(ISNUMBER(SEARCH("rs2",D5)),CHAR(10) & SUBSTITUTE(DONOTDELETE!$A$17,"INSTR",SUBSTITUTE(LOWER($C5),".","_")),"") | M5: COVERED-GVSOC | N5: corev_rand_pulp_instr_test:A/C2 pulp_post_increment_load_store:A/C1
E6: coverage: All bits of rs1 are toggled All bits of Imm12 are toggled All bits of rD are toggled | F6: Check against RM | G6: Constrained-Random | H6: see CV32E40Pv2_test_list.xlsx | I6: Functional Coverage | J6: corev_rand_pulp_instr_test pulp_post_increment_load_store | K6: =SUBSTITUTE(DONOTDELETE!$A$15,"INSTR",SUBSTITUTE(LOWER($C5),".","_")) & IF(ISNUMBER(SEARCH("rs2",D5)),CHAR(10) & SUBSTITUTE(DONOTDELETE!$A$18,"INSTR",SUBSTITUTE(LOWER($C5),".","_")),"") | L6: Toggle is not a requirement of CV32E40Pv2 verification, but the corresponding coverage from the Reference Model Coverage Package exists and is given for reference purposes only. Immediate toggle coverage is missing from Reference Model Coverage Package. | M6: COVERED-GVSOC | N6: corev_rand_pulp_instr_test:A/C2 pulp_post_increment_load_store:A/C1
E7: Constraints: The instructions generated are precedeed by a multicycle F instruction | F7: Check against RM | G7: Constrained-Random | H7: see CV32E40Pv2_test_list.xlsx | I7: Functional Coverage | J7: corev_rand_fp_instr_mlt_cyc_test | M7: COVERED-GVSOC | N7: corev_rand_fp_instr_mlt_cyc_test:A
C8: CV.LH.II | D8: cv.lh rD, Imm(rs1!) rD = Sext(Mem16(rs1)) rs1 += Sext(Imm[11:0]) | E8: Register operands All possible rs1 registers are used. All possible rD registers are used. All possible register combinations where first operand is the destination register of the previous instruction | F8: Check against RM | G8: Constrained-Random | H8: see CV32E40Pv2_test_list.xlsx | I8: Functional Coverage | J8: corev_rand_pulp_instr_test pulp_post_increment_load_store | K8: =SUBSTITUTE(DONOTDELETE!$A$14,"INSTR",SUBSTITUTE(LOWER($C8),".","_")) & IF(ISNUMBER(SEARCH("rs2",D8)),CHAR(10) & SUBSTITUTE(DONOTDELETE!$A$17,"INSTR",SUBSTITUTE(LOWER($C8),".","_")),"") | M8: COVERED-GVSOC | N8: corev_rand_pulp_instr_test:A/C2 pulp_post_increment_load_store:A/C1
E9: coverage: All bits of rs1 are toggled All bits of Imm12 are toggled All bits of rD are toggled | F9: Check against RM | G9: Constrained-Random | H9: see CV32E40Pv2_test_list.xlsx | I9: Functional Coverage | J9: corev_rand_pulp_instr_test pulp_post_increment_load_store | K9: =SUBSTITUTE(DONOTDELETE!$A$15,"INSTR",SUBSTITUTE(LOWER($C8),".","_")) & IF(ISNUMBER(SEARCH("rs2",D8)),CHAR(10) & SUBSTITUTE(DONOTDELETE!$A$18,"INSTR",SUBSTITUTE(LOWER($C8),".","_")),"") | L9: Toggle is not a requirement of CV32E40Pv2 verification, but the corresponding coverage from the Reference Model Coverage Package exists and is given for reference purposes only. Immediate toggle coverage is missing from Reference Model Coverage Package. | M9: COVERED-GVSOC | N9: corev_rand_pulp_instr_test:A/C2 pulp_post_increment_load_store:A/C1
E10: Constraints: The instructions generated are precedeed by a multicycle F instruction | F10: Check against RM | G10: Constrained-Random | H10: see CV32E40Pv2_test_list.xlsx | I10: Functional Coverage | J10: corev_rand_fp_instr_mlt_cyc_test | M10: COVERED-GVSOC | N10: corev_rand_fp_instr_mlt_cyc_test:A
C11: CV.LHU.II | D11: cv.lhu rD, Imm(rs1!) rD = Zext(Mem16(rs1)) rs1 += Sext(Imm[11:0]) | E11: Register operands All possible rs1 registers are used. All possible rD registers are used. All possible register combinations where first operand is the destination register of the previous instruction | F11: Check against RM | G11: Constrained-Random | H11: see CV32E40Pv2_test_list.xlsx | I11: Functional Coverage | J11: corev_rand_pulp_instr_test pulp_post_increment_load_store | K11: =SUBSTITUTE(DONOTDELETE!$A$14,"INSTR",SUBSTITUTE(LOWER($C11),".","_")) & IF(ISNUMBER(SEARCH("rs2",D11)),CHAR(10) & SUBSTITUTE(DONOTDELETE!$A$17,"INSTR",SUBSTITUTE(LOWER($C11),".","_")),"") | M11: COVERED-GVSOC | N11: corev_rand_pulp_instr_test:A/C2 pulp_post_increment_load_store:A/C1
E12: coverage: All bits of rs1 are toggled All bits of Imm12 are toggled All bits of rD are toggled | F12: Check against RM | G12: Constrained-Random | H12: see CV32E40Pv2_test_list.xlsx | I12: Functional Coverage | J12: corev_rand_pulp_instr_test pulp_post_increment_load_store | K12: =SUBSTITUTE(DONOTDELETE!$A$15,"INSTR",SUBSTITUTE(LOWER($C11),".","_")) & IF(ISNUMBER(SEARCH("rs2",D11)),CHAR(10) & SUBSTITUTE(DONOTDELETE!$A$18,"INSTR",SUBSTITUTE(LOWER($C11),".","_")),"") | L12: Toggle is not a requirement of CV32E40Pv2 verification, but the corresponding coverage from the Reference Model Coverage Package exists and is given for reference purposes only. Immediate toggle coverage is missing from Reference Model Coverage Package. | M12: COVERED-GVSOC | N12: corev_rand_pulp_instr_test:A/C2 pulp_post_increment_load_store:A/C1
E13: Constraints: The instructions generated are precedeed by a multicycle F instruction | F13: Check against RM | G13: Constrained-Random | H13: see CV32E40Pv2_test_list.xlsx | I13: Functional Coverage | J13: corev_rand_fp_instr_mlt_cyc_test | M13: COVERED-GVSOC | N13: corev_rand_fp_instr_mlt_cyc_test:A
C14: CV.LW.II | D14: cv.lw rD, Imm(rs1!) rD = Mem32(rs1) rs1 += Sext(Imm[11:0]) | E14: Register operands All possible rs1 registers are used. All possible rD registers are used. All possible register combinations where first operand is the destination register of the previous instruction | F14: Check against RM | G14: Constrained-Random | H14: see CV32E40Pv2_test_list.xlsx | I14: Functional Coverage | J14: corev_rand_pulp_instr_test pulp_post_increment_load_store | K14: =SUBSTITUTE(DONOTDELETE!$A$14,"INSTR",SUBSTITUTE(LOWER($C14),".","_")) & IF(ISNUMBER(SEARCH("rs2",D14)),CHAR(10) & SUBSTITUTE(DONOTDELETE!$A$17,"INSTR",SUBSTITUTE(LOWER($C14),".","_")),"") | M14: COVERED-GVSOC | N14: corev_rand_pulp_instr_test:A/C2 pulp_post_increment_load_store:A/C1
E15: coverage: All bits of rs1 are toggled All bits of Imm12 are toggled All bits of rD are toggled | F15: Check against RM | G15: Constrained-Random | H15: see CV32E40Pv2_test_list.xlsx | I15: Functional Coverage | J15: corev_rand_pulp_instr_test pulp_post_increment_load_store | K15: =SUBSTITUTE(DONOTDELETE!$A$15,"INSTR",SUBSTITUTE(LOWER($C14),".","_")) & IF(ISNUMBER(SEARCH("rs2",D14)),CHAR(10) & SUBSTITUTE(DONOTDELETE!$A$18,"INSTR",SUBSTITUTE(LOWER($C14),".","_")),"") | L15: Toggle is not a requirement of CV32E40Pv2 verification, but the corresponding coverage from the Reference Model Coverage Package exists and is given for reference purposes only. Immediate toggle coverage is missing from Reference Model Coverage Package. | M15: COVERED-GVSOC | N15: corev_rand_pulp_instr_test:A/C2 pulp_post_increment_load_store:A/C1
E16: Constraints: The instructions generated are precedeed by a multicycle F instruction | F16: Check against RM | G16: Constrained-Random | H16: see CV32E40Pv2_test_list.xlsx | I16: Functional Coverage | J16: corev_rand_fp_instr_mlt_cyc_test | M16: COVERED-GVSOC | N16: corev_rand_fp_instr_mlt_cyc_test:A
B17: Load Operations - Register-Register Loads with Post-Increment | C17: CV.LB.RI | D17: cv.lb rD, rs2(rs1!) rD = Sext(Mem8(rs1)) rs1 += rs2 | E17: Register operands All possible rs1 registers are used. All possible rs2 registers are used. All possible rD registers are used. All possible register combinations where first operand is the destination register of the previous instruction All possible register combinations where second operand is the destination register of the previous instruction | F17: Check against RM | G17: Constrained-Random | H17: see CV32E40Pv2_test_list.xlsx | I17: Functional Coverage | J17: corev_rand_pulp_instr_test pulp_post_increment_load_store | K17: =SUBSTITUTE(DONOTDELETE!$A$14,"INSTR",SUBSTITUTE(LOWER($C17),".","_")) & IF(ISNUMBER(SEARCH("rs2",D17)),CHAR(10) & SUBSTITUTE(DONOTDELETE!$A$17,"INSTR",SUBSTITUTE(LOWER($C17),".","_")),"") | M17: COVERED-GVSOC | N17: corev_rand_pulp_instr_test:A/C2 pulp_post_increment_load_store:A/C1
E18: coverage: All bits of rs1 are toggled All bits of rs2 are toggled All bits of rD are toggled | F18: Check against RM | G18: Constrained-Random | H18: see CV32E40Pv2_test_list.xlsx | I18: Functional Coverage | J18: corev_rand_pulp_instr_test pulp_post_increment_load_store | K18: =SUBSTITUTE(DONOTDELETE!$A$15,"INSTR",SUBSTITUTE(LOWER($C17),".","_")) & IF(ISNUMBER(SEARCH("rs2",D17)),CHAR(10) & SUBSTITUTE(DONOTDELETE!$A$18,"INSTR",SUBSTITUTE(LOWER($C17),".","_")),"") | L18: Toggle is not a requirement of CV32E40Pv2 verification, but the corresponding coverage from the Reference Model Coverage Package exists and is given for reference purposes only | M18: COVERED-GVSOC | N18: corev_rand_pulp_instr_test:A/C2 pulp_post_increment_load_store:A/C1
E19: Constraints: The instructions generated are precedeed by a multicycle F instruction | F19: Check against RM | G19: Constrained-Random | H19: see CV32E40Pv2_test_list.xlsx | I19: Functional Coverage | J19: corev_rand_fp_instr_mlt_cyc_test | M19: COVERED-GVSOC | N19: corev_rand_fp_instr_mlt_cyc_test:A
C20: CV.LBU.RI | D20: cv.lbu rD, rs2(rs1!) rD = Zext(Mem8(rs1)) rs1 += rs2 | E20: Register operands All possible rs1 registers are used. All possible rs2 registers are used. All possible rD registers are used. All possible register combinations where first operand is the destination register of the previous instruction All possible register combinations where second operand is the destination register of the previous instruction | F20: Check against RM | G20: Constrained-Random | H20: see CV32E40Pv2_test_list.xlsx | I20: Functional Coverage | J20: corev_rand_pulp_instr_test pulp_post_increment_load_store | K20: =SUBSTITUTE(DONOTDELETE!$A$14,"INSTR",SUBSTITUTE(LOWER($C20),".","_")) & IF(ISNUMBER(SEARCH("rs2",D20)),CHAR(10) & SUBSTITUTE(DONOTDELETE!$A$17,"INSTR",SUBSTITUTE(LOWER($C20),".","_")),"") | M20: COVERED-GVSOC | N20: corev_rand_pulp_instr_test:A/C2 pulp_post_increment_load_store:A/C1
E21: coverage: All bits of rs1 are toggled All bits of rs2 are toggled All bits of rD are toggled | F21: Check against RM | G21: Constrained-Random | H21: see CV32E40Pv2_test_list.xlsx | I21: Functional Coverage | J21: corev_rand_pulp_instr_test pulp_post_increment_load_store | K21: =SUBSTITUTE(DONOTDELETE!$A$15,"INSTR",SUBSTITUTE(LOWER($C20),".","_")) & IF(ISNUMBER(SEARCH("rs2",D20)),CHAR(10) & SUBSTITUTE(DONOTDELETE!$A$18,"INSTR",SUBSTITUTE(LOWER($C20),".","_")),"") | L21: Toggle is not a requirement of CV32E40Pv2 verification, but the corresponding coverage from the Reference Model Coverage Package exists and is given for reference purposes only | M21: COVERED-GVSOC | N21: corev_rand_pulp_instr_test:A/C2 pulp_post_increment_load_store:A/C1
E22: Constraints: The instructions generated are precedeed by a multicycle F instruction | F22: Check against RM | G22: Constrained-Random | H22: see CV32E40Pv2_test_list.xlsx | I22: Functional Coverage | J22: corev_rand_fp_instr_mlt_cyc_test | M22: COVERED-GVSOC | N22: corev_rand_fp_instr_mlt_cyc_test:A
C23: CV.LH.RI | D23: cv.lh rD, rs2(rs1!) rD = Sext(Mem16(rs1)) rs1 += rs2 | E23: Register operands All possible rs1 registers are used. All possible rs2 registers are used. All possible rD registers are used. All possible register combinations where first operand is the destination register of the previous instruction All possible register combinations where second operand is the destination register of the previous instruction | F23: Check against RM | G23: Constrained-Random | H23: see CV32E40Pv2_test_list.xlsx | I23: Functional Coverage | J23: corev_rand_pulp_instr_test pulp_post_increment_load_store | K23: =SUBSTITUTE(DONOTDELETE!$A$14,"INSTR",SUBSTITUTE(LOWER($C23),".","_")) & IF(ISNUMBER(SEARCH("rs2",D23)),CHAR(10) & SUBSTITUTE(DONOTDELETE!$A$17,"INSTR",SUBSTITUTE(LOWER($C23),".","_")),"") | M23: COVERED-GVSOC | N23: corev_rand_pulp_instr_test:A/C2 pulp_post_increment_load_store:A/C1
E24: coverage: All bits of rs1 are toggled All bits of rs2 are toggled All bits of rD are toggled | F24: Check against RM | G24: Constrained-Random | H24: see CV32E40Pv2_test_list.xlsx | I24: Functional Coverage | J24: corev_rand_pulp_instr_test pulp_post_increment_load_store | K24: =SUBSTITUTE(DONOTDELETE!$A$15,"INSTR",SUBSTITUTE(LOWER($C23),".","_")) & IF(ISNUMBER(SEARCH("rs2",D23)),CHAR(10) & SUBSTITUTE(DONOTDELETE!$A$18,"INSTR",SUBSTITUTE(LOWER($C23),".","_")),"") | L24: Toggle is not a requirement of CV32E40Pv2 verification, but the corresponding coverage from the Reference Model Coverage Package exists and is given for reference purposes only | M24: COVERED-GVSOC | N24: corev_rand_pulp_instr_test:A/C2 pulp_post_increment_load_store:A/C1
E25: Constraints: The instructions generated are precedeed by a multicycle F instruction | F25: Check against RM | G25: Constrained-Random | H25: see CV32E40Pv2_test_list.xlsx | I25: Functional Coverage | J25: corev_rand_fp_instr_mlt_cyc_test | M25: COVERED-GVSOC | N25: corev_rand_fp_instr_mlt_cyc_test:A
C26: CV.LHU.RI | D26: cv.lhu rD, rs2(rs1!) rD = Zext(Mem16(rs1)) rs1 += rs2 | E26: Register operands All possible rs1 registers are used. All possible rs2 registers are used. All possible rD registers are used. All possible register combinations where first operand is the destination register of the previous instruction All possible register combinations where second operand is the destination register of the previous instruction | F26: Check against RM | G26: Constrained-Random | H26: see CV32E40Pv2_test_list.xlsx | I26: Functional Coverage | J26: corev_rand_pulp_instr_test pulp_post_increment_load_store | K26: =SUBSTITUTE(DONOTDELETE!$A$14,"INSTR",SUBSTITUTE(LOWER($C26),".","_")) & IF(ISNUMBER(SEARCH("rs2",D26)),CHAR(10) & SUBSTITUTE(DONOTDELETE!$A$17,"INSTR",SUBSTITUTE(LOWER($C26),".","_")),"") | M26: COVERED-GVSOC | N26: corev_rand_pulp_instr_test:A/C2 pulp_post_increment_load_store:A/C1
E27: coverage: All bits of rs1 are toggled All bits of rs2 are toggled All bits of rD are toggled | F27: Check against RM | G27: Constrained-Random | H27: see CV32E40Pv2_test_list.xlsx | I27: Functional Coverage | J27: corev_rand_pulp_instr_test pulp_post_increment_load_store | K27: =SUBSTITUTE(DONOTDELETE!$A$15,"INSTR",SUBSTITUTE(LOWER($C26),".","_")) & IF(ISNUMBER(SEARCH("rs2",D26)),CHAR(10) & SUBSTITUTE(DONOTDELETE!$A$18,"INSTR",SUBSTITUTE(LOWER($C26),".","_")),"") | L27: Toggle is not a requirement of CV32E40Pv2 verification, but the corresponding coverage from the Reference Model Coverage Package exists and is given for reference purposes only | M27: COVERED-GVSOC | N27: corev_rand_pulp_instr_test:A/C2 pulp_post_increment_load_store:A/C1
E28: Constraints: The instructions generated are precedeed by a multicycle F instruction | F28: Check against RM | G28: Constrained-Random | H28: see CV32E40Pv2_test_list.xlsx | I28: Functional Coverage | J28: corev_rand_fp_instr_mlt_cyc_test | M28: COVERED-GVSOC | N28: corev_rand_fp_instr_mlt_cyc_test:A
C29: CV.LW.RI | D29: cv.lw rD, rs2(rs1!) rD = Mem32(rs1) rs1 += rs2 | E29: Register operands All possible rs1 registers are used. All possible rs2 registers are used. All possible rD registers are used. All possible register combinations where first operand is the destination register of the previous instruction All possible register combinations where second operand is the destination register of the previous instruction | F29: Check against RM | G29: Constrained-Random | H29: see CV32E40Pv2_test_list.xlsx | I29: Functional Coverage | J29: corev_rand_pulp_instr_test pulp_post_increment_load_store | K29: =SUBSTITUTE(DONOTDELETE!$A$14,"INSTR",SUBSTITUTE(LOWER($C29),".","_")) & IF(ISNUMBER(SEARCH("rs2",D29)),CHAR(10) & SUBSTITUTE(DONOTDELETE!$A$17,"INSTR",SUBSTITUTE(LOWER($C29),".","_")),"") | M29: COVERED-GVSOC | N29: corev_rand_pulp_instr_test:A/C2 pulp_post_increment_load_store:A/C1
E30: coverage: All bits of rs1 are toggled All bits of rs2 are toggled All bits of rD are toggled | F30: Check against RM | G30: Constrained-Random | H30: see CV32E40Pv2_test_list.xlsx | I30: Functional Coverage | J30: corev_rand_pulp_instr_test pulp_post_increment_load_store | K30: =SUBSTITUTE(DONOTDELETE!$A$15,"INSTR",SUBSTITUTE(LOWER($C29),".","_")) & IF(ISNUMBER(SEARCH("rs2",D29)),CHAR(10) & SUBSTITUTE(DONOTDELETE!$A$18,"INSTR",SUBSTITUTE(LOWER($C29),".","_")),"") | L30: Toggle is not a requirement of CV32E40Pv2 verification, but the corresponding coverage from the Reference Model Coverage Package exists and is given for reference purposes only | M30: COVERED-GVSOC | N30: corev_rand_pulp_instr_test:A/C2 pulp_post_increment_load_store:A/C1
E31: Constraints: The instructions generated are precedeed by a multicycle F instruction | F31: Check against RM | G31: Constrained-Random | H31: see CV32E40Pv2_test_list.xlsx | I31: Functional Coverage | J31: corev_rand_fp_instr_mlt_cyc_test | M31: COVERED-GVSOC | N31: corev_rand_fp_instr_mlt_cyc_test:A
B32: Load Operations - Register-Register Loads | C32: CV.LB.R | D32: cv.lb rD, rs2, rs1 rD = Sext(mem8(rs1 + rs2)) | E32: Register operands All possible rs1 registers are used. All possible rs2 registers are used. All possible rD registers are used. All possible register combinations where first operand is the destination register of the previous instruction All possible register combinations where second operand is the destination register of the previous instruction | F32: Check against RM | G32: Constrained-Random | H32: see CV32E40Pv2_test_list.xlsx | I32: Functional Coverage | J32: corev_rand_pulp_instr_test pulp_post_increment_load_store | K32: =SUBSTITUTE(DONOTDELETE!$A$14,"INSTR",SUBSTITUTE(LOWER($C32),".","_")) & IF(ISNUMBER(SEARCH("rs2",D32)),CHAR(10) & SUBSTITUTE(DONOTDELETE!$A$17,"INSTR",SUBSTITUTE(LOWER($C32),".","_")),"") | M32: COVERED-GVSOC | N32: corev_rand_pulp_instr_test:A/C2 pulp_post_increment_load_store:A/C1
E33: coverage: All bits of rs1 are toggled All bits of rs2 are toggled All bits of rD are toggled | F33: Check against RM | G33: Constrained-Random | H33: see CV32E40Pv2_test_list.xlsx | I33: Functional Coverage | J33: corev_rand_pulp_instr_test pulp_post_increment_load_store | K33: =SUBSTITUTE(DONOTDELETE!$A$15,"INSTR",SUBSTITUTE(LOWER($C32),".","_")) & IF(ISNUMBER(SEARCH("rs2",D32)),CHAR(10) & SUBSTITUTE(DONOTDELETE!$A$18,"INSTR",SUBSTITUTE(LOWER($C32),".","_")),"") | L33: Toggle is not a requirement of CV32E40Pv2 verification, but the corresponding coverage from the Reference Model Coverage Package exists and is given for reference purposes only | M33: COVERED-GVSOC | N33: corev_rand_pulp_instr_test:A/C2 pulp_post_increment_load_store:A/C1
E34: Constraints: The instructions generated are precedeed by a multicycle F instruction | F34: Check against RM | G34: Constrained-Random | H34: see CV32E40Pv2_test_list.xlsx | I34: Functional Coverage | J34: corev_rand_fp_instr_mlt_cyc_test | M34: COVERED-GVSOC | N34: corev_rand_fp_instr_mlt_cyc_test:A
C35: CV.LBU.R | D35: cv.lbu rD, rs2(rs1!) rD = Zext(Mem8(rs1)) | E35: Register operands All possible rs1 registers are used. All possible rs2 registers are used. All possible rD registers are used. All possible register combinations where first operand is the destination register of the previous instruction All possible register combinations where second operand is the destination register of the previous instruction | F35: Check against RM | G35: Constrained-Random | H35: see CV32E40Pv2_test_list.xlsx | I35: Functional Coverage | J35: corev_rand_pulp_instr_test pulp_post_increment_load_store | K35: =SUBSTITUTE(DONOTDELETE!$A$14,"INSTR",SUBSTITUTE(LOWER($C35),".","_")) & IF(ISNUMBER(SEARCH("rs2",D35)),CHAR(10) & SUBSTITUTE(DONOTDELETE!$A$17,"INSTR",SUBSTITUTE(LOWER($C35),".","_")),"") | M35: COVERED-GVSOC | N35: corev_rand_pulp_instr_test:A/C2 pulp_post_increment_load_store:A/C1
E36: coverage: All bits of rs1 are toggled All bits of rs2 are toggled All bits of rD are toggled | F36: Check against RM | G36: Constrained-Random | H36: see CV32E40Pv2_test_list.xlsx | I36: Functional Coverage | J36: corev_rand_pulp_instr_test pulp_post_increment_load_store | K36: =SUBSTITUTE(DONOTDELETE!$A$15,"INSTR",SUBSTITUTE(LOWER($C35),".","_")) & IF(ISNUMBER(SEARCH("rs2",D35)),CHAR(10) & SUBSTITUTE(DONOTDELETE!$A$18,"INSTR",SUBSTITUTE(LOWER($C35),".","_")),"") | L36: Toggle is not a requirement of CV32E40Pv2 verification, but the corresponding coverage from the Reference Model Coverage Package exists and is given for reference purposes only | M36: COVERED-GVSOC | N36: corev_rand_pulp_instr_test:A/C2 pulp_post_increment_load_store:A/C1
E37: Constraints: The instructions generated are precedeed by a multicycle F instruction | F37: Check against RM | G37: Constrained-Random | H37: see CV32E40Pv2_test_list.xlsx | I37: Functional Coverage | J37: corev_rand_fp_instr_mlt_cyc_test | M37: COVERED-GVSOC | N37: corev_rand_fp_instr_mlt_cyc_test:A
C38: CV.LH.R | D38: cv.lh rD, rs2(rs1!) rD = Sext(Mem16(rs1)) | E38: Register operands All possible rs1 registers are used. All possible rs2 registers are used. All possible rD registers are used. All possible register combinations where first operand is the destination register of the previous instruction All possible register combinations where second operand is the destination register of the previous instruction | F38: Check against RM | G38: Constrained-Random | H38: see CV32E40Pv2_test_list.xlsx | I38: Functional Coverage | J38: corev_rand_pulp_instr_test pulp_post_increment_load_store | K38: =SUBSTITUTE(DONOTDELETE!$A$14,"INSTR",SUBSTITUTE(LOWER($C38),".","_")) & IF(ISNUMBER(SEARCH("rs2",D38)),CHAR(10) & SUBSTITUTE(DONOTDELETE!$A$17,"INSTR",SUBSTITUTE(LOWER($C38),".","_")),"") | M38: COVERED-GVSOC | N38: corev_rand_pulp_instr_test:A/C2 pulp_post_increment_load_store:A/C1
E39: coverage: All bits of rs1 are toggled All bits of rs2 are toggled All bits of rD are toggled | F39: Check against RM | G39: Constrained-Random | H39: see CV32E40Pv2_test_list.xlsx | I39: Functional Coverage | J39: corev_rand_pulp_instr_test pulp_post_increment_load_store | K39: =SUBSTITUTE(DONOTDELETE!$A$15,"INSTR",SUBSTITUTE(LOWER($C38),".","_")) & IF(ISNUMBER(SEARCH("rs2",D38)),CHAR(10) & SUBSTITUTE(DONOTDELETE!$A$18,"INSTR",SUBSTITUTE(LOWER($C38),".","_")),"") | L39: Toggle is not a requirement of CV32E40Pv2 verification, but the corresponding coverage from the Reference Model Coverage Package exists and is given for reference purposes only | M39: COVERED-GVSOC | N39: corev_rand_pulp_instr_test:A/C2 pulp_post_increment_load_store:A/C1
E40: Constraints: The instructions generated are precedeed by a multicycle F instruction | F40: Check against RM | G40: Constrained-Random | H40: see CV32E40Pv2_test_list.xlsx | I40: Functional Coverage | J40: corev_rand_fp_instr_mlt_cyc_test | M40: COVERED-GVSOC | N40: corev_rand_fp_instr_mlt_cyc_test:A
...

Sheet DONOTDELETE
A1: Pass/Fail Criteria | C1: Test Type | E1: Coverage Method
A2: Self Checking Test | C2: RISC-V Compliance | E2: Testcase
A3: Signature Check | C3: OpenHW Compliance | E3: Functional Coverage
A4: Check against ISS | C4: Directed Self-Checking | E4: Assertion Coverage
A5: Check against RM | C5: Directed Non-Self-Checking | E5: Code Coverage
A6: Assertion Check | C6: Constrained-Random
A7: Other | C7: Other
A14: CG: RISCV_coverage_pkg.RISCV_coverage__1.INSTR_cg.cp_rs1 CG: RISCV_coverage_pkg.RISCV_coverage__1.INSTR_cg.cp_gpr_hazard[RAW_HAZARD] CG: RISCV_coverage_pkg.RISCV_coverage__1.INSTR_cg.cp_rd
A15: CG: RISCV_coverage_pkg.RISCV_coverage__1.INSTR_cg.cp_rd_toggle CG: RISCV_coverage_pkg.RISCV_coverage__1.INSTR_cg.cp_rs1_toggle
A17: CG: RISCV_coverage_pkg.RISCV_coverage__1.INSTR_cg.cp_rs2
A18: CG: RISCV_coverage_pkg.RISCV_coverage__1.INSTR_cg.cp_rs2_toggle

Sheet GVSOC_provenance
A1: GVSOC ISS parity annotation
A3: Data audit | B3: 2026-08-12
A4: Reference model | B4: GVSOC iss_v2 (RVVI DPI step-and-compare), sostituisce ImperasDV nella stessa TB
A5: Revisione ISS | B5: core 9f275f6f / pulp 66b648a / gvsoc 3401620 / gvsoc_rvvi f2a6adc / cvv 2b9d33a1d
A6: Evidenza | B6: quick_val full gate 2026-08-11: 155 PASS / 0 FAIL / 3 known-fail / 2 skip - evidenza /data2/marco.paci/validation-evidence/quickval_gate_20260811_c2/
A7: Metodo | B7: Colonne GVSOC affiancate al tracciamento originale; item-level da CV32E40Pv2_test_list + lane quick_val (160 lane, 4 config)
